Failure # 1 (occurred at 2025-02-27_11-40-59)
[36mray::PPO.restore()[39m (pid=16688, ip=127.0.0.1, actor_id=d1ea0afb32c36554b4ba414101000000, repr=PPO)
  File "python\ray\_raylet.pyx", line 1883, in ray._raylet.execute_task
  File "python\ray\_raylet.pyx", line 1824, in ray._raylet.execute_task.function_executor
  File "C:\Users\Owner\anaconda3\Lib\site-packages\ray\_private\function_manager.py", line 696, in actor_method_executor
    return method(__ray_actor, *args, **kwargs)
           ^^^^^^^^^^^^^^^^^^^^^^^^^^^^^^^^^^^^
  File "C:\Users\Owner\anaconda3\Lib\site-packages\ray\util\tracing\tracing_helper.py", line 463, in _resume_span
    return method(self, *_args, **_kwargs)
           ^^^^^^^^^^^^^^^^^^^^^^^^^^^^^^^
  File "C:\Users\Owner\anaconda3\Lib\site-packages\ray\tune\trainable\trainable.py", line 554, in restore
    raise ValueError(
ValueError: Could not recover from checkpoint as it does not exist on storage anymore. Got storage fs type `local` and path: C:/Users/Owner/Desktop/m148/m148-MAS-Communication/with_seer_results/PPO_werewolf-v1_18563_00000_0_2025-02-27_09-20-09/checkpoint_000002
