Failure # 1 (occurred at 2025-03-03_21-56-56)
[36mray::PPO.train()[39m (pid=22476, ip=127.0.0.1, actor_id=537c5c2c3736f38ae37fbace01000000, repr=PPO)
  File "python\ray\_raylet.pyx", line 1883, in ray._raylet.execute_task
  File "python\ray\_raylet.pyx", line 1824, in ray._raylet.execute_task.function_executor
  File "C:\Users\Owner\anaconda3\Lib\site-packages\ray\_private\function_manager.py", line 696, in actor_method_executor
    return method(__ray_actor, *args, **kwargs)
           ^^^^^^^^^^^^^^^^^^^^^^^^^^^^^^^^^^^^
  File "C:\Users\Owner\anaconda3\Lib\site-packages\ray\util\tracing\tracing_helper.py", line 463, in _resume_span
    return method(self, *_args, **_kwargs)
           ^^^^^^^^^^^^^^^^^^^^^^^^^^^^^^^
  File "C:\Users\Owner\anaconda3\Lib\site-packages\ray\tune\trainable\trainable.py", line 331, in train
    raise skipped from exception_cause(skipped)
  File "C:\Users\Owner\anaconda3\Lib\site-packages\ray\tune\trainable\trainable.py", line 328, in train
    result = self.step()
             ^^^^^^^^^^^
  File "C:\Users\Owner\anaconda3\Lib\site-packages\ray\util\tracing\tracing_helper.py", line 463, in _resume_span
    return method(self, *_args, **_kwargs)
           ^^^^^^^^^^^^^^^^^^^^^^^^^^^^^^^
  File "C:\Users\Owner\anaconda3\Lib\site-packages\ray\rllib\algorithms\algorithm.py", line 1027, in step
    ) = self._run_one_training_iteration_old_api_stack()
        ^^^^^^^^^^^^^^^^^^^^^^^^^^^^^^^^^^^^^^^^^^^^^^^^
  File "C:\Users\Owner\anaconda3\Lib\site-packages\ray\util\tracing\tracing_helper.py", line 463, in _resume_span
    return method(self, *_args, **_kwargs)
           ^^^^^^^^^^^^^^^^^^^^^^^^^^^^^^^
  File "C:\Users\Owner\anaconda3\Lib\site-packages\ray\rllib\algorithms\algorithm.py", line 4011, in _run_one_training_iteration_old_api_stack
    training_step_results = self.training_step()
                            ^^^^^^^^^^^^^^^^^^^^
  File "C:\Users\Owner\anaconda3\Lib\site-packages\ray\util\tracing\tracing_helper.py", line 463, in _resume_span
    return method(self, *_args, **_kwargs)
           ^^^^^^^^^^^^^^^^^^^^^^^^^^^^^^^
  File "C:\Users\Owner\anaconda3\Lib\site-packages\ray\rllib\algorithms\ppo\ppo.py", line 392, in training_step
    return self._training_step_old_api_stack()
           ^^^^^^^^^^^^^^^^^^^^^^^^^^^^^^^^^^^
  File "C:\Users\Owner\anaconda3\Lib\site-packages\ray\util\tracing\tracing_helper.py", line 463, in _resume_span
    return method(self, *_args, **_kwargs)
           ^^^^^^^^^^^^^^^^^^^^^^^^^^^^^^^
  File "C:\Users\Owner\anaconda3\Lib\site-packages\ray\rllib\algorithms\ppo\ppo.py", line 519, in _training_step_old_api_stack
    kl_divergence = policy_info[LEARNER_STATS_KEY].get("kl")
                    ~~~~~~~~~~~^^^^^^^^^^^^^^^^^^^
KeyError: 'learner_stats'
